Module 20) Debugging and Problem Solving with Python
Assignment 1: Syntax Errors
Objective:
Identify and fix basic syntax errors in the Python program.
Problem:
The following Python program should calculate the sum of two numbers, but it contains
several syntax errors. Fix the errors and ensure the program runs correctly.
python
def addNumbers(a, b):
result = a + b
return result
number1 = input("Enter the first number:")
number2 = input("Enter the second number:")
sum = addNumbers(number1 number2)
print "The sum is:", sum
Task:

 Identify the syntax errors and correct them.

To fix the syntax errors in the provided Python program, here are the necessary corrections:

The addNumbers function should be properly indented.
The input function in Python 3 returns a string, so we need to convert the input to integers before performing the addition.
There is a missing comma between number1 and number2 when calling addNumbers.
The print statement in Python 3 requires parentheses.
Here's the corrected version of the program:

python
def addNumbers(a, b):
    result = a + b
    return result

# Convert the input to integers
number1 = int(input("Enter the first number: "))
number2 = int(input("Enter the second number: "))

# Fix the function call by adding a comma between the arguments
sum_result = addNumbers(number1, number2)

# Correct the print statement to use parentheses
print("The sum is:", sum_result)
Key Changes:
Indented the code properly.
Converted inputs to integers using int().
Fixed the function call to include a comma between number1 and number2.
Corrected the print statement by adding parentheses (required in Python 3).


 Explain the corrected issues (e.g., missing commas, incorrect function calls, etc.).

1. Indentation Error
In Python, indentation is crucial for defining blocks of code within functions, loops, and conditionals. The line result = a + b needs to be indented properly to be part of the addNumbers function.
2. Input Handling
The input() function returns a string. If you want to perform arithmetic operations on the inputs (like addition), you'll need to convert the input strings to numbers (either integers or floats).
In the original code, number1 and number2 are strings, so they need to be converted to integers (or floats) before performing the addition.
3. Incorrect Function Call
The line sum = addNumbers(number1 number2) has a syntax error. There should be a comma between number1 and number2 when calling the function.
4. Print Statement Syntax
In Python 3, print is a function and must be called with parentheses. The original code is using the Python 2 syntax, which is not valid in Python 3.
Corrected Code:
python
def addNumbers(a, b):
    result = a + b
    return result

number1 = int(input("Enter the first number: "))  # Convert to integer
number2 = int(input("Enter the second number: "))  # Convert to integer

sum = addNumbers(number1, number2)  # Correct function call with comma

print("The sum is:", sum)  # Use parentheses for print in Python 3
Explanation of Fixes:
Indentation: The result = a + b line inside the function is indented to indicate it's part of the function body.

Input Conversion:

The input() function returns a string, so we use int() to convert the input into integers. You can also use float() if you expect decimal numbers.
Function Call: The correct syntax for calling the function addNumbers() is to pass two arguments, number1 and number2, separated by a comma.

Print Statement: The print function is now correctly used with parentheses, which is the correct syntax in Python 3.

Assignment 2: Logical Errors
Objective:
Understand and resolve logical errors in Python code.
Problem:
The Python program has a few issues that need to be corrected:

The function name check even odd contains spaces, which is not allowed in Python function names. It should be a valid identifier, like check_even_odd.
The if statement uses a single = sign, which is an assignment operator. To compare values, you should use the == equality operator.
There's a typo in the function call checck_even_odd(number) (it has an extra 'c' in checck).
There is also a small issue with the comma in the print statement in the else block. It should end with a period, not a comma.
Here’s the corrected version of the program:

python
The provided Python program appears to be logically correct at first glance. The function check_even_odd is designed to check if a number is even or odd by using the modulo operator (%). The modulo operator calculates the remainder when dividing the number by 2. If the remainder is 0 (i.e., num % 2 == 0), the number is even, and it will print "The number is even." Otherwise, it will print "The number is odd."

If the program always prints "The number is even," even when the number is odd, the issue likely lies elsewhere. The problem could occur due to one of the following reasons:

1. Input Handling Issue
The way the user input is being entered could be problematic, especially if there is any hidden character or if the user enters non-numeric input. For example, if a non-numeric value (e.g., a string or special character) is entered, the program may not behave as expected, even though this isn't an issue in the provided code directly.

2. Code Execution Context
There may be an issue with the environment where the program is running, such as a bug in the IDE, a persistent state from a previous run, or a misconfiguration in the Python interpreter.

 Describe how this type of error impacts the flow of the program.

However, based on the code provided, no logical flaw is apparent, and the program should work correctly for typical even and odd checks.

Impact of This Error
If the program always prints "The number is even," the program fails to accurately identify whether the entered number is even or odd. This could:

Mislead the user into thinking that the number is always even, even when it's odd.
Hinder the program’s intended functionality because it does not provide the correct output for odd numbers, making the function unreliable.
Cause confusion when testing or debugging, as it doesn't behave as expected.
xplanation of the fixes:
Function name: The function name is changed to check_even_odd without spaces.
Comparison operator: The equality operator == is used in the if statement to check if the number is even.
Typo in function call: The function call checck_even_odd(number) is corrected to check_even_odd(number).
Comma to period: The print statement in the else block is corrected to end with a period.

Assignment 3: Index and Range Errors
Objective:
Fix indexing errors and prevent out-of-range issues in lists.
Problem:
The following code attempts to access and print the first three elements of a list, but it raises
an IndexError. Identify and correct the problem.
python
my_list = [10, 20]
print(my_list[0])
print(my_list[1])
print(my_list[2]) # This line causes an error
Task:

 Identify the issue and provide a solution to prevent IndexError.

The issue with the provided code is that the list my_list only contains two elements: [10, 20]. However, the code tries to access the third element using my_list[2], which causes an IndexError because the list has no element at index 2 (indices start at 0).

Correct Solution:
Solution 1: Adjust the number of elements accessed. If you only want to print the elements that are available in the list, you can access only the first two elements. You can fix this by modifying the code as follows:
python
my_list = [10, 20]
print(my_list[0])  # Prints 10
print(my_list[1])  # Prints 20
Solution 2: Prevent errors by checking the length of the list. If you want to safely print elements without causing an error, you can add a check to ensure you don't access an index that is out of range:
python

my_list = [10, 20]
for i in range(min(3, len(my_list))):  # Ensures no index exceeds the length of the list
    print(my_list[i])
In this second solution, the min(3, len(my_list)) ensures that you don't try to access more elements than are available in the list, which prevents the IndexError.

 Write an explanation of list indices and how out-of-range access can be avoided.

The issue in the given code is that the list my_list contains only two elements (10 and 20), and you are attempting to access the element at index 2 with print(my_list[2]). Since the list has only indices 0 and 1, the index 2 is out of range, causing an IndexError.

Correcting the code:
To avoid the error, you should ensure that you're accessing indices that exist within the bounds of the list. Since my_list only has two elements, you can only access the elements at indices 0 and 1.

Here’s the corrected code:

python
my_list = [10, 20]
print(my_list[0])
print(my_list[1])
# print(my_list[2])  # This line causes an error since there is no index 2.
Alternatively, if you want to safely access the first three elements, you could add more elements to the list:

python
my_list = [10, 20, 30]
print(my_list[0])
print(my_list[1])
print(my_list[2])
Explanation of List Indices and Avoiding Out-of-Range Access:
List Indices: In Python, list elements are indexed starting from 0. For example:

my_list[0] refers to the first element.
my_list[1] refers to the second element, and so on.
Out-of-Range Access: If you try to access an index that does not exist in the list (e.g., my_list[2] in a list with only two elements), Python raises an IndexError. This is because the list doesn't have an element at that index.

Avoiding Out-of-Range Errors:

Check the length of the list: Before accessing an index, ensure that it is less than the length of the list. For example:
python
if index < len(my_list):
    print(my_list[index])
else:
    print("Index out of range")
Use a loop: If you want to print multiple elements from a list, you can use a loop to avoid accessing indices out of range:
python
for i in range(min(3, len(my_list))):  # Ensures we don't go beyond the list's length
    print(my_list[i])

Assignment 4: Type Errors
Objective:
Debug and resolve type mismatch errors in Python programs.
Problem:
The following program tries to concatenate a string and an integer, but it raises a TypeError.
Fix the error and make the program functional.
python
name = input("Enter your name: ")
age = int(input("Enter your age: "))
greeting = "Hello, " + name + ". You are " + age + " years old."
print(greeting)
Task:
 Debug the type error in the code and provide a solution.

The error occurs because you're trying to concatenate a string ("Hello, ", ". You are ", and " years old.") with an integer (age), which causes a TypeError. In Python, you can only concatenate strings with other strings, so you need to convert the age (which is an integer) into a string before concatenating it.

Here's the corrected code:
python
name = input("Enter your name: ")
age = int(input("Enter your age: "))
greeting = "Hello, " + name + ". You are " + str(age) + " years old."
print(greeting)
Explanation of the Fix:
The str(age) converts the integer age to a string so that it can be concatenated with the other strings.

 Explain why Python throws a TypeError when trying to concatenate a string and an integer.

The issue in the program arises because Python doesn't automatically convert the age integer into a string when you try to concatenate it with other strings. In Python, you can only concatenate strings with other strings. Trying to concatenate a string with an integer directly results in a TypeError.

Fixing the Error
To fix this error, we need to convert the age integer to a string before concatenating it with the other strings. You can do this using the str() function:

python
name = input("Enter your name: ")
age = int(input("Enter your age: "))
greeting = "Hello, " + name + ". You are " + str(age) + " years old."
print(greeting)
Explanation of the TypeError
Python throws a TypeError because it expects both operands to be of the same type when performing string concatenation using the + operator. When trying to concatenate a string ("Hello, " or " years old.") with an integer (age), Python does not automatically convert the integer to a string. Thus, it raises an error because you are trying to concatenate an incompatible type (int) with a string.

To resolve this, we explicitly convert the integer (age) into a string using the str() function, allowing Python to perform the concatenation correctly.


Assignment 5: Infinite Loops
Objective:
Fix an infinite loop issue and understand how control flow works in loops.
Problem:
The following code is supposed to print numbers from 1 to 10, but it never stops. Identify the
cause and fix the infinite loop.
python
counter = 1
while counter <= 10:
print(counter)
Task:
 Debug the infinite loop and correct it.

The issue with the code is that the counter is not being incremented inside the while loop. This causes the condition counter <= 10 to always be true, leading to an infinite loop.

Here's the corrected code:
python
counter = 1
while counter <= 10:
    print(counter)
    counter += 1  # Increment counter to avoid infinite loop
Explanation:
The counter += 1 statement ensures that the counter is increased by 1 after each iteration, which will eventually make the condition counter <= 10 false, allowing the loop to terminate.

 Explain the importance of controlling loop conditions to avoid infinite loops

The code you provided has an issue where the loop doesn't stop because the counter variable is never updated inside the loop. Here's the original code:

python
counter = 1
while counter <= 10:
    print(counter)
Issue:
The loop condition checks whether counter <= 10. If counter is never updated within the loop, it will remain 1, and the condition counter <= 10 will always be true, causing an infinite loop.
Fix:
To resolve this, you need to increment the counter variable inside the loop so that eventually the condition counter <= 10 will become false, and the loop will terminate. Here's the corrected version of the code:

python
counter = 1
while counter <= 10:
    print(counter)
    counter += 1  # Increment the counter to avoid an infinite loop
Explanation:
counter += 1: This line increments the value of counter by 1 in each iteration of the loop. Eventually, when counter exceeds 10, the condition counter <= 10 will be false, and the loop will terminate.
Importance of Controlling Loop Conditions:
Preventing Infinite Loops: Properly controlling the loop conditions is essential to prevent infinite loops, which can cause the program to hang or consume excessive system resources.
Ensuring Program Efficiency: Infinite loops can lead to inefficient code execution, potentially locking up the program, consuming memory or CPU resources indefinitely, and making debugging difficult.
Maintaining Program Flow: Correctly managing loop termination conditions ensures that the program runs as intended and exits the loop when the task is completed.

Assignment 6: Off-by-One Errors
Objective:
Understand and fix off-by-one errors in loops.
Problem:
The following code is designed to print numbers from 1 to 5, but it only prints numbers from
1 to 4. Debug and fix the issue.
python
for i in range(1, 5):
print(i)
Task:

 Identify the off-by-one error and correct the code.

The issue in the given code is that the range(1, 5) function generates numbers starting from 1 up to, but not including 5. This is causing the loop to print numbers from 1 to 4, but not 5.

To include 5 in the output, you should change the range(1, 5) to range(1, 6).

Corrected code:
python
for i in range(1, 6):
    print(i)
This will print numbers from 1 to 5.

 Explain how Python's range() function works and how to properly specify loop ranges.

The issue with the given code is in the usage of the range() function. The code is written as:

python
for i in range(1, 5):
    print(i)
This code is intended to print numbers from 1 to 5, but it only prints numbers from 1 to 4. This is due to how the range() function works in Python.

Explanation of Python's range() function:
In Python, the range() function generates a sequence of numbers. It can take up to three arguments:

Start (optional): The number from which the sequence starts. If not provided, it defaults to 0.
Stop: The number at which the sequence stops, but it is not included in the range.
Step (optional): The difference between each pair of numbers in the sequence. If not provided, it defaults to 1.
The range() function generates a sequence starting from the start value and goes up to, but does not include, the stop value.

How to Fix the Issue:
To print numbers from 1 to 5 (inclusive), you need to adjust the stop value in range(). Since the stop value is exclusive, you should set it to 6 instead of 5:

python
for i in range(1, 6):  # Set the stop value to 6
    print(i)
Explanation of the Fix:
range(1, 6) starts at 1 and generates numbers up to 5, but it will not include 6.
The output will be:
1
2
3
4
5
This now prints the numbers 1 through 5, as expected.

Assignment 7: Uninitialized Variables
Objective:
Debug and correct uninitialized variable issues in Python programs.
Problem:
The following code attempts to print a variable result without initializing it first. Identify
and fix the issue.
python
Copy code
def multiply(a, b):
result = a * b
multiply(5,10)
print(result)# This line causes an error
Task:

 Debug the code and ensure that the variable result is initialized correctly.

The issue in the code is that the variable result is defined inside the multiply function, but you are trying to access it outside of the function, where it is not in scope. To fix this, you can either:

Return the result from the multiply function and print it outside.
Print result directly within the function after calculating it.
Here's how you can fix the code by returning the result:

Fixed Code:
python
def multiply(a, b):
    result = a * b
    return result  # Return the result

# Call the function and store the result
result = multiply(5, 10)

# Print the result outside the function
print(result)
Explanation:
The multiply function now returns the result of the multiplication.
The result variable is assigned the returned value from the multiply(5, 10) call.
Finally, the result is printed outside the function.
This ensures that the variable result is properly initialized before it is used.

 Explain the importance of variable initialization in Python.
Assignment

The issue in the provided code is that the variable result is being used outside the function where it was defined. In Python, variables are scoped to the function or block where they are initialized. Since result is defined within the multiply function, it is not accessible outside of that function.

Issue
The line print(result) causes an error because result is not defined in the global scope. The variable result is local to the multiply function and cannot be accessed outside it.

Solution
To fix this, the result should either be returned by the multiply function and then printed outside the function, or result can be defined in the global scope.

Here's the corrected version:

python
def multiply(a, b):
    result = a * b
    return result  # Return the result

# Now call the function and store the result in a variable
result = multiply(5, 10)

# Print the result
print(result)  # This will print 50
Explanation of Variable Initialization in Python
In Python, variables must be initialized before they are used. This is because Python is a dynamically-typed language, and it doesn't know what type of value a variable will hold until it is assigned one. If you try to access a variable before assigning it a value, Python will raise a NameError because the interpreter doesn't know about that variable.

Importance of Initialization:
Avoid Errors: Using uninitialized variables results in runtime errors. Always initialize a variable before use.
Predictability: Initialization ensures that your code behaves predictably by assigning a value to the variable, making it clear what data the variable holds.
Debugging: Uninitialized variables can cause bugs that are hard to trace. Proper initialization helps avoid this issue.
In summary, always ensure variables are initialized with values before using them to avoid errors like the one in the original code.

Assignment 8: Function Call Errors
Objective:
Debug issues related to incorrect function calls and argument passing.
Problem:
The following program is meant to calculate the area of a rectangle, but it produces an error
due to incorrect function arguments. Fix the function call error.
python
def calculate_area(length, width):
return length * width
l = 10
area = calculate_area(l) # Missing second argument
print("The area is:", area)
Task:

 Debug the error and fix the function call by passing the correct number of arguments.

The error in your code is due to the incorrect number of arguments being passed to the calculate_area function. The function calculate_area requires two arguments: length and width. However, in the call calculate_area(l), only one argument (l, which is 10) is passed, and the second argument is missing.

To fix this, you need to pass both length and width to the function. Here's the corrected version of the code:

python
def calculate_area(length, width):
    return length * width

l = 10
w = 5  # Example value for width
area = calculate_area(l, w)  # Pass both length and width
print("The area is:", area)
Explanation of Changes:
I added a second variable w for the width, with an example value of 5.
The function calculate_area is now called with both l (length) and w (width) as arguments.
Now, the program will correctly calculate the area of the rectangle and print it. For example, with l = 10 and w = 5, it will output:

csharp
The area is: 50

 Explain the concept of function arguments and how Python handles function calls.

The error in the program occurs because the function calculate_area() expects two arguments (length and width), but only one argument (l, which is 10) is passed in the function call calculate_area(l).

Fixing the Error
To fix the error, you need to provide both arguments required by the calculate_area function. The function takes two arguments—length and width. Since the value for width is missing in the call, we need to supply both values. Here's the corrected code:

python
def calculate_area(length, width):
    return length * width

l = 10
w = 5  # Assume width is 5
area = calculate_area(l, w)  # Provide both length and width
print("The area is:", area)
In this corrected version, I assumed width to be 5 (but you can replace it with any valid value).

Explanation of Function Arguments and Function Calls in Python:
Function Arguments:

When you define a function in Python (such as calculate_area(length, width)), the function expects certain arguments to be passed when it is called. These arguments are the values or variables that the function operates on.
In this case, length and width are the parameters of the function calculate_area, and they are required to calculate the area of a rectangle.
Function Calls:

When calling a function, you provide values (called arguments) corresponding to the parameters defined in the function.
If a function expects two arguments, you must pass two values in the function call. If you fail to do so, Python will raise an error because it doesn't know what values to assign to the parameters.
For example, in the original call:

python
area = calculate_area(l)  # Error: only one argument passed
Python raises an error because it expects a second argument for width.

How Python Handles Function Calls:

When you call a function like calculate_area(l, w), Python matches the values you provide (l and w) with the function's parameters (length and width).
The first argument (l = 10) is assigned to the first parameter (length), and the second argument (w = 5) is assigned to the second parameter (width).
The function then performs the operation (length * width), and returns the result, which is printed.

Assignment 9: Scope and Variable Shadowing
Objective:
Understand and fix scope-related issues in Python.
Problem:
The following code attempts to modify a global variable inside a function, but the changes
are not reflected outside the function. Debug the issue related to variable scope.
python
counter = 0
def increment_counter():
counter += 1
increment_counter()
print("Counter:", counter)
Task:

 Debug the issue related to variable scope and explain how Python handles variable
shadowing.

The issue in the given code is related to how Python handles variable scope, especially with regard to global and local variables. In the function increment_counter(), the variable counter is being modified with the += operation, but Python interprets counter as a local variable because it is assigned a new value (even though it's not explicitly declared as local in the code). As a result, the global variable counter remains unchanged outside the function, and no modification is reflected.

Explanation:
Global variable: counter is defined at the global scope with an initial value of 0.
Local variable in function: Inside the function increment_counter(), the statement counter += 1 attempts to modify counter. This creates a new local variable named counter and tries to assign it the result of counter + 1, which is where the problem occurs. Since there's no global declaration inside the function, Python treats counter as a local variable and raises an error if you try to access or modify it before it's assigned a value locally.
Solution:
To modify the global variable counter inside the function, you need to explicitly tell Python that you're working with the global variable. You can do this by using the global keyword inside the function.

Corrected Code:
python
counter = 0  # Global variable

def increment_counter():
    global counter  # Indicate that we are modifying the global counter
    counter += 1  # Modify the global counter

increment_counter()
print("Counter:", counter)  # This will now print: Counter: 1
Explanation of the Fix:
global counter: This tells Python that we want to modify the global counter variable, not create a local one. Without this declaration, Python would treat counter as a local variable inside the function.
Scope: With the global keyword, the function operates on the global counter rather than a new local variable. Any changes to counter inside the function are now reflected outside the function.
Python Variable Shadowing:
Shadowing occurs when a variable in a local scope has the same name as a variable in an outer (global) scope. The local variable "shadows" or hides the outer variable within that scope.
Without the global keyword in this case, Python treats counter as a local variable and doesn't modify the global one.

 Modify the code so that the function can modify the global variable correctly.

The issue with the code is that the variable counter is treated as a local variable inside the function increment_counter() because it is assigned a new value within the function. In Python, if you assign a value to a variable inside a function, it will be considered local to that function unless explicitly declared as global.

To modify the global variable correctly, you need to use the global keyword to tell Python that you are referring to the global counter variable instead of creating a new local one.

Here's the corrected version of the code:

python
counter = 0

def increment_counter():
    global counter  # Declare counter as a global variable
    counter += 1

increment_counter()
print("Counter:", counter)
Explanation:
The global keyword tells Python that the counter inside the function refers to the global counter variable.
Without the global keyword, Python treats counter as a local variable, so the global counter is not modified.
After running this modified code, the output will be:

makefile
Counter: 1

Assignment 10: Debugging with try-except Blocks
Objective:
Use try-except blocks to handle exceptions and debug runtime errors.
Problem:
The following code prompts the user to input two numbers and divides them, but it raises a
ZeroDivisionError when the second number is zero. Handle the exception using a tryexcept
block.
python
num1 = int(input("Enter the first number: "))
num2 = int(input("Enter the second number: "))
result = num1 / num2
print("Result:", result)
Task:

 Use try-except blocks to handle the ZeroDivisionError and provide a meaningful
error message to the user.

To handle the ZeroDivisionError in your code and provide a meaningful error message, you can use a try-except block. Here's how you can modify your code:

python
try:
    num1 = int(input("Enter the first number: "))
    num2 = int(input("Enter the second number: "))
    result = num1 / num2
    print("Result:", result)
except ZeroDivisionError:
    print("Error: Cannot divide by zero. Please enter a non-zero second number.")
except ValueError:
    print("Error: Invalid input. Please enter valid integers.")
Explanation:
try block: Contains the code that might raise an exception (in this case, the division operation).
except ZeroDivisionError: Catches the ZeroDivisionError and displays a custom message when the user tries to divide by zero.
except ValueError: Catches cases where the user inputs something that can't be converted to an integer (e.g., non-numeric input).

 Explain how exception handling improves the robustness of Python programs.

To handle the ZeroDivisionError in your Python program, you can use a try-except block to catch the exception and handle it gracefully. Here's the modified code:

python
try:
    num1 = int(input("Enter the first number: "))
    num2 = int(input("Enter the second number: "))
    result = num1 / num2
    print("Result:", result)
except ZeroDivisionError:
    print("Error: Cannot divide by zero!")
except ValueError:
    print("Error: Please enter valid integers.")
Explanation:
try block: This is where the code that may raise an exception is placed. In this case, the division operation (num1 / num2) could raise a ZeroDivisionError if num2 is zero, or a ValueError if the user enters invalid input (e.g., non-integer values).

except ZeroDivisionError: This block will handle the case when the second number is zero, preventing the program from crashing and instead displaying a friendly error message ("Error: Cannot divide by zero!").

except ValueError: This additional except block catches errors caused by invalid input (like when the user enters something other than a number), preventing the program from throwing an error and instead informing the user of the issue.

Graceful Handling: Instead of allowing the program to crash, we catch the error and provide meaningful feedback to the user.

How Exception Handling Improves Robustness in Python Programs:
Error Prevention: Exception handling allows you to prevent the program from abruptly terminating due to unexpected errors. By anticipating potential problems (like division by zero), you can catch exceptions and deal with them appropriately without losing control of the program.

User Experience: It improves the user experience by providing clear, helpful error messages instead of cryptic error traceback. This makes it easier for users to understand what went wrong and how to correct it.

Maintainability: When exceptions are handled correctly, it makes your code more maintainable because you can isolate and manage potential issues in specific blocks of code. This prevents errors from propagating and causing larger failures.

Flexibility: You can create more flexible programs that can handle a wider range of inputs and conditions without crashing. For example, you can allow users to retry inputs or provide fallback mechanisms for certain types of errors.

Debugging: Exception handling helps during development by logging or displaying useful error information, making it easier to identify where problems arise. You can even add a generic except Exception as e block to capture unexpected errors and log them for later debugging.

Assignment 11: File Handling Errors
Objective:
Debug and handle file-related errors in Python programs.
Problem:
The following code tries to open a file that may not exist, causing a FileNotFoundError.
Handle this error and ensure the program works correctly.
python
file = open("data.txt", "r")
content = file.read()
print(content)
file.close()
Task:

 Use try-except to handle file opening errors and provide a fallback message when the file
does not exist.

To handle the FileNotFoundError and ensure the program works correctly, you can use a try-except block around the code that opens the file. If the file doesn't exist, it will print a fallback message instead of crashing. Here's the updated code:

python
try:
    # Try to open the file in read mode
    file = open("data.txt", "r")
    
    # Read and print the content of the file
    content = file.read()
    print(content)
    
    # Close the file after reading
    file.close()

except FileNotFoundError:
    # Handle the case when the file does not exist
    print("The file 'data.txt' was not found. Please check the file path.")
Explanation:
try block: This is where the code attempts to open and read the file.
except FileNotFoundError block: This block catches the FileNotFoundError if the file doesn't exist, and it prints a helpful message.

 Explain the importance of exception handling when working with files.

To handle the FileNotFoundError in your code, we can use a try and except block to catch the error if the file doesn't exist. Here's the corrected code with proper exception handling:

python
try:
    file = open("data.txt", "r")
    content = file.read()
    print(content)
    file.close()
except FileNotFoundError:
    print("The file 'data.txt' was not found. Please check the file path.")
Explanation:
try Block: This is where you place the code that might raise an exception. In this case, trying to open and read a file.

except FileNotFoundError Block: This block catches the specific exception (FileNotFoundError) and allows you to handle it gracefully. If the file is not found, the program will print an error message and continue without crashing.

Why Use Exception Handling When Working with Files?

File Availability: Files may not exist, or there might be permission issues. Handling these exceptions ensures that the program doesn’t crash unexpectedly when these issues arise.

Graceful Error Messages: Instead of a traceback or program crash, exception handling allows you to provide clear, user-friendly messages or take corrective action, like creating the file if needed or logging the error.

Program Continuity: By catching exceptions, you can ensure that your program continues to run smoothly, even if it encounters issues while working with external resources like files.

Maintainability: Exception handling improves the readability and maintainability of your code, as it prevents your program from failing without proper feedback. It lets you define fallback mechanisms, like asking the user for another file path or creating a new file.

Assignment 12: Logic Errors in Algorithms
Objective:
Identify and correct logic errors in simple algorithms.
Problem:
The following code is supposed to find the maximum number in a list, but it always prints the
first number as the maximum. Debug the issue.
python
def find_max(numbers):
max_num = numbers[0]
for num in numbers:
if num>max_num:
   max_num=num
return max_num
nums = [3, 7, 2, 8, 4]
print("Maximum number is:", find_max(nums))
Task:

 Debug the logic error and fix the issue.

The issue with the provided code is that the comparison if num > max_num: starts with max_num as the first element of the list and continues to compare it against all numbers, including the first number itself. The issue here is that the initial assignment of max_num = numbers[0] is correct, but the loop should start at the second element (index 1) to avoid mistakenly comparing the first element with itself.

Here's the corrected version of the code:

python
def find_max(numbers):
    max_num = numbers[0]  # Initialize with the first element
    for num in numbers[1:]:  # Start the loop from the second element
        if num > max_num:
            max_num = num
    return max_num

nums = [3, 7, 2, 8, 4]
print("Maximum number is:", find_max(nums))
Explanation of the changes:
The loop now starts at the second element (numbers[1:]), so it compares the first element only once and proceeds to check the rest.
The rest of the logic remains the same, where the function checks if the current number (num) is greater than max_num and updates max_num accordingly.
Now, this should correctly find the maximum number in the list. The output will be:

csharp
Maximum number is: 8

 Explain how comparison works in Python and why the current logic fails.

The issue in your code arises due to improper indentation of the code block inside the find_max function. In Python, indentation is crucial as it defines the scope of loops, conditionals, and function definitions. The if statement and return statement should be properly indented within the function.

Debugged Code:
python
def find_max(numbers):
    max_num = numbers[0]  # Start with the first number as the initial maximum
    for num in numbers:    # Loop through the list
        if num > max_num:  # If the current number is greater than the current max
            max_num = num  # Update max_num with the current number
    return max_num         # Return the final maximum value

nums = [3, 7, 2, 8, 4]
print("Maximum number is:", find_max(nums))
Explanation of the Fix:
The original code was likely not producing the correct output because the if condition (to check if num > max_num) and the logic to update max_num were either incorrectly indented or outside the scope of the loop. In the corrected version, both the if condition and the assignment max_num = num are properly indented inside the for loop.

Explanation of Comparison in Python:
Comparison Operator: In Python, the comparison operator > is used to compare two values. It checks if the value on the left side of the operator is greater than the value on the right side. If it is, the condition evaluates to True; otherwise, it evaluates to False.

Why the Original Logic Failed:

In your original code, even though the logic for finding the maximum was conceptually correct, Python requires the correct indentation for the loop and conditionals to work. The condition if num > max_num is only valid if it's inside the loop, where it compares each number with the current max_num. Without proper indentation, the loop doesn't run properly, causing incorrect behavior, such as always printing the first number as the maximum.

Output of the Debugged Code:
When you run the corrected version of the code, the output will be:

csharp
Maximum number is: 8
